Workbook

Sheet 成本&报价
A1: 汇率 | B1: 8.76 | C1: 1元=8.76比索 | D1: 20260320汇率
A2: 序号 | B2: 设备名称 | C2: 数量 | D2: 单价 Unit Price | E2: 单位 | F2: 总价 | G2: 备注 | H2: 利润率 | J2: 组件数 | K2: 组串数
A3: =ROW()-2 -> 1 | B3: 逆变器 50k 220 | C3: 2 | D3: =201000/B1*1.13+400 -> 26328.082 | E3: 台 | F3: =C3*D3 -> 52656.164 | H3: 0.92 | J3: 16 | K3: 6
A4: =ROW()-2 -> 2 | B4: 光伏组件 | C4: 168 | D4: =0.84*630 -> 529.2 | E4: 片 | F4: =C4*D4 -> 88905.6 | H4: 0.92 | J4: 17 | K4: 0
A5: =ROW()-2 -> 3 | B5: 光伏支架 | C5: =C4 -> 168 | D5: =0.1331*630 -> 83.853 | E5: 套 | F5: =C5*D5 -> 14087.304 | H5: 0.7 | J5: 18 | K5: =(C4-J3*K3-J4*K4)/J5 -> 4
A6: =ROW()-2 -> 4 | B6: MC4 | C6: =_xlfn.CEILING.MATH(SUM(K3:K5)*4*1.1,10) -> 50 | D6: 5.5 | E6: 套 | F6: =C6*D6 -> 275 | H6: 0.7
A7: =ROW()-2 -> 5 | B7: 组串RSD连接器,PEFS-EL40H-20-P2,接10串 | C7: 1 | D7: 2951 | E7: 套 | F7: =C7*D7 -> 2951 | H7: 0.7
A8: =ROW()-2 -> 6 | B8: RSD 紧急旋钮 | C8: 1 | D8: 56 | E8: 个 | F8: =C8*D8 -> 56 | H8: 0.7
A9: =ROW()-2 -> 7 | B9: 直流线缆 | C9: =_xlfn.CEILING.MATH(C15/138.88*3000,100) -> 2300 | D9: 4.6 | E9: 米 | F9: =C9*D9 -> 10580 | H9: 0.7
A10: =ROW()-2 -> 8 | B10: 交流电缆 | C10: 100 | D10: 500 | E10: 米 | F10: =C10*D10 -> 50000 | H10: 0.7
A11: =ROW()-2 -> 9 | B11: 防逆流表&互感器 | C11: 1 | D11: 1510 | E11: 台 | F11: =C11*D11 -> 1510 | H11: 0.7
A12: =ROW()-2 -> 10 | B12: SmartControl 箱 | C12: 1 | D12: 3000 | E12: 个 | F12: =C12*D12 -> 3000 | H12: 0.7
A13: =ROW()-2 -> 11 | B13: AC 配电箱 | C13: 1 | D13: 2510 | E13: 个 | F13: =C13*D13 -> 2510 | H13: 0.7
A14: =ROW()-2 -> 12 | B14: DC 配电箱 | C14: 1 | D14: 3960 | E14: 个 | F14: =C14*D14 -> 3960 | H14: 0.7
A15: =ROW()-2 -> 13 | B15: 施工费 | C15: =630*C4/1000 -> 105.84 | D15: 400 | F15: =C15*D15 -> 42336 | H15: 0.7
A16: =ROW()-2 -> 14 | B16: 报关、运输海运费 | C16: 0.5 | D16: 8260 | F16: =C16*D16 -> 4130 | H16: 0.7
A17: =ROW()-2 -> 15 | B17: 系统调试人员费用 | C17: 2.4 | D17: 3000 | E17: 人天 | F17: =C17*D17 -> 7200 | H17: 1
A18: =ROW()-2 -> 16 | B18: 电网接入费用 | C18: 0 | F18: =C18*D18 -> 0
A19: =ROW()-2 -> 17 | B19: 其他费用 | C19: 0 | F19: =C19*D19 -> 0
A20: 18
A22: 1 | B22: 设备成本 | C22: =SUM(F3:F14) -> 230491.07
A23: 2 | B23: 建设成本&耗材 | C23: =CEILING(F15, 100) -> 42400
A24: 3 | B24: 报关、物流费 | C24: =CEILING(F16, 100) -> 4200
A25: 4 | B25: 系统调试人员费用 | C25: =CEILING(F17, 100) -> 7200
A26: 5 | B26: 电网接入费用
B27: 总费用（成本） | C27: =SUM(C22:C26) -> 284291.07
A30: ID. | B30: Description | C30: Quantity | D30: Unit Price | E30: Unit | F30: Total Price
A31: =A3 -> 1 | B31: Solar Inverter | C31: =C3 -> 2 | D31: =D3*$B$1 -> 230634 | E31: Set | F31: =D31*C31 -> 461268
A32: =A4 -> 2 | B32: PV Modules | C32: =C4 -> 168 | D32: =D4*$B$1 -> 4635.792 | E32: pcs | F32: =D32*C32 -> 778813.06
A33: =A5 -> 3 | B33: Mounting Structure | C33: =C5 -> 168 | D33: =D5*$B$1 -> 734.55228 | E33: pcs | F33: =D33*C33 -> 123404.78
A34: =A6 -> 4 | B34: MC4 Connectors | C34: =C6 -> 50 | D34: =D6*$B$1 -> 48.18 | E34: Pair | F34: =D34*C34 -> 2409
A35: =A7 -> 5 | B35: Rapid Shutdown Device (RSD) | C35: =C7 -> 1 | D35: =D7*$B$1 -> 25850.76 | E35: pcs | F35: =D35*C35 -> 25850.76
A36: =A8 -> 6 | B36: RSD emergency stop button | C36: =C8 -> 1 | D36: =D8*$B$1 -> 490.56 | E36: Set | F36: =D36*C36 -> 490.56
A37: =A9 -> 7 | B37: DC Cables | C37: =C9 -> 2300 | D37: =D9*$B$1 -> 40.296 | E37: m | F37: =D37*C37 -> 92680.8
A38: =A10 -> 8 | B38: AC Cables | C38: =C10 -> 100 | D38: =D10*$B$1 -> 4380 | E38: m | F38: =D38*C38 -> 438000
A39: =A11 -> 9 | B39: Anti-Reflux Smart Meter & Current Transformer （CT) | C39: =C11 -> 1 | D39: =D11*$B$1 -> 13227.6 | E39: Pair | F39: =D39*C39 -> 13227.6
A40: =A12 -> 10 | B40: SmartControl Box | C40: =C12 -> 1 | D40: =D12*$B$1 -> 26280 | E40: Set | F40: =D40*C40 -> 26280
A41: =A13 -> 11 | B41: AC Distribution Box | C41: =C13 -> 1 | D41: =D13*$B$1 -> 21987.6 | E41: Set | F41: =D41*C41 -> 21987.6
A42: =A14 -> 12 | B42: DC Distribution Box | C42: =C14 -> 1 | D42: =D14*$B$1 -> 34689.6 | E42: Set | F42: =D42*C42 -> 34689.6
A43: =A15 -> 13 | B43: On-site Construction | C43: 1 | D43: =C23*$B$1 -> 371424 | E43: Lot | F43: =D43*C43 -> 371424
...

Sheet 收益
A1: 汇率 | B1: ='成本&报价'!B1 -> 8.76
B2: total piso | C2: Generation Charge | D2: VAT RATES | E2: Transmission Charge perkw | F2: VAT RATES | G2: System Loss Charge | H2: VAT RATES | I2: Distribution Charge | J2: Distribution Charge perkw | K2: Supply Charge4 | L2: Metering Charge | M2: Metering percut | N2: Current RPT Charge | O2: UC-ME for 15 (NPC-SPUG) | P2: UC-ME for (RED-CI) | Q2: UC-EC1 | R2: UC-SD | S2: Fit-All (Renewable) | T2: VAT RATES | U2: 需量 | V2: 电量
A3: jan | B3: =C3*(1+D3)+G3*(1+H3)+(I3+L3+N3+O3+P3+R3+S3+Q3)*(1+T3) -> 9.184892 | C3: 6.8358 | D3: 0.1122 | E3: 293.28 | F3: 0.1039 | G3: 0.636 | H3: 0.1112 | I3: 0.1339 | J3: 232.2 | K3: 827.54 | L3: 0.335 | M3: 831.72 | N3: 0.0039 | O3: 0.1805 | P3: 0.0017 | Q3: 0 | R3: 0.0428 | S3: 0.0838 | T3: 0.12
A4: Feb | B4: =C4*(1+D4)+G4*(1+H4)+(I4+L4+N4+O4+P4+R4+S4+Q4)*(1+T4) -> 9.675147 | C4: 7.2203 | D4: 0.1126 | E4: 285.62 | F4: 0.1044 | G4: 0.6707 | H4: 0.1117 | I4: 0.1339 | J4: 232.2 | K4: 827.54 | L4: 0.335 | M4: 831.72 | N4: 0.0054 | O4: 0.1949 | P4: 0.0044 | Q4: 0 | R4: 0.0428 | S4: 0.0838 | T4: 0.12
A5: Mar | B5: =C5*(1+D5)+G5*(1+H5)+(I5+L5+N5+O5+P5+R5+S5+Q5)*(1+T5) -> 9.5470556 | C5: 7.0517 | D5: 0.1153 | E5: 325.14 | F5: 0.1032 | G5: 0.6704 | H5: 0.1139 | I5: 0.1339 | J5: 232.2 | K5: 827.54 | L5: 0.335 | M5: 831.72 | N5: 0.0054 | O5: 0.1949 | P5: 0.0044 | Q5: 0 | R5: 0.0428 | S5: 0.1189 | T5: 0.12
A6: Apr | B6: =C6*(1+D6)+G6*(1+H6)+(I6+L6+N6+O6+P6+R6+S6+Q6)*(1+T6) -> 10.398407 | C6: 7.7795 | D6: 0.1113 | E6: 370.13 | F6: 0.1082 | G6: 0.7358 | H6: 0.1109 | I6: 0.1339 | J6: 232.2 | K6: 827.54 | L6: 0.335 | M6: 831.72 | N6: 0.0055 | O6: 0.1949 | P6: 0.0044 | Q6: 0 | R6: 0.0428 | S6: 0.1189 | T6: 0.12
A7: May | B7: =C7*(1+D7)+G7*(1+H7)+(I7+L7+N7+O7+P7+R7+S7+Q7)*(1+T7) -> 9.9851299 | C7: 7.4651 | D7: 0.1122 | E7: 273.68 | F7: 0.1076 | G7: 0.6715 | H7: 0.1118 | I7: 0.1339 | J7: 232.2 | K7: 827.54 | L7: 0.335 | M7: 831.72 | N7: 0.0057 | O7: 0.1949 | P7: 0.0044 | Q7: 0 | R7: 0.0428 | S7: 0.1189 | T7: 0.12
A8: Jun | B8: =C8*(1+D8)+G8*(1+H8)+(I8+L8+N8+O8+P8+R8+S8+Q8)*(1+T8) -> 9.8563446 | C8: 7.3552 | D8: 0.1143 | E8: 276.79 | F8: 0.108 | G8: 0.6506 | H8: 0.1137 | I8: 0.1339 | J8: 232.2 | K8: 827.54 | L8: 0.335 | M8: 831.72 | N8: 0.0057 | O8: 0.1949 | P8: 0.0044 | Q8: 0 | R8: 0.0428 | S8: 0.1189 | T8: 0.12
A9: Jul | B9: =C9*(1+D9)+G9*(1+H9)+(I9+L9+N9+O9+P9+R9+S9+Q9)*(1+T9) -> 10.261719 | C9: 7.6959 | D9: 0.1147 | E9: 295.5 | F9: 0.1081 | G9: 0.6706 | H9: 0.1141 | I9: 0.1339 | J9: 232.2 | K9: 827.54 | L9: 0.335 | M9: 831.72 | N9: 0.0058 | O9: 0.1949 | P9: 0.0044 | Q9: 0 | R9: 0.0428 | S9: 0.1189 | T9: 0.12
A10: Aug | B10: =C10*(1+D10)+G10*(1+H10)+(I10+L10+N10+O10+P10+R10+S10+Q10)*(1+T10) -> 10.741601 | C10: 8.0708 | D10: 0.1172 | E10: 336.63 | F10: 0.1098 | G10: 0.7066 | H10: 0.1165 | I10: 0.1339 | J10: 232.2 | K10: 827.54 | L10: 0.335 | M10: 831.72 | N10: 0.0058 | O10: 0.1949 | P10: 0.0044 | Q10: 0 | R10: 0.0428 | S10: 0.1189 | T10: 0.12
A11: Sep | B11: =C11*(1+D11)+G11*(1+H11)+(I11+L11+N11+O11+P11+R11+S11+Q11)*(1+T11) -> 10.427683 | C11: 7.8105 | D11: 0.117 | E11: 387.72 | F11: 0.1117 | G11: 0.6873 | H11: 0.1165 | I11: 0.1339 | J11: 232.2 | K11: 827.54 | L11: 0.335 | M11: 831.72 | N11: 0.0058 | O11: 0.1949 | P11: 0.0044 | Q11: 0 | R11: 0.0428 | S11: 0.1189 | T11: 0.12
A12: Oct | B12: =C12*(1+D12)+G12*(1+H12)+(I12+L12+N12+O12+P12+R12+S12+Q12)*(1+T12) -> 10.654436 | C12: 8.008 | D12: 0.1163 | E12: 373.36 | F12: 0.112 | G12: 0.6981 | H12: 0.1159 | I12: 0.1339 | J12: 232.2 | K12: 827.54 | L12: 0.335 | M12: 831.72 | N12: 0.0059 | O12: 0.1949 | P12: 0.0044 | Q12: 0 | R12: 0.0428 | S12: 0.1189 | T12: 0.12
A13: Nov | B13: =C13*(1+D13)+G13*(1+H13)+(I13+L13+N13+O13+P13+R13+S13+Q13)*(1+T13) -> 10.644662 | C13: 7.9 | D13: 0.1139 | E13: 439.67 | F13: 0.1124 | G13: 0.7245 | H13: 0.1138 | I13: 0.1339 | J13: 232.2 | K13: 827.54 | L13: 0.335 | M13: 831.72 | N13: 0.0059 | O13: 0.1949 | P13: 0.0044 | Q13: 0.0025 | R13: 0.0428 | S13: 0.2073 | T13: 0.12
A14: Dec | B14: =C14*(1+D14)+G14*(1+H14)+(I14+L14+N14+O14+P14+R14+S14+Q14)*(1+T14) -> 10.458848 | C14: 7.7642 | D14: 0.1136 | E14: 373.76 | F14: 0.107 | G14: 0.6962 | H14: 0.1128 | I14: 0.1339 | J14: 232.2 | K14: 827.54 | L14: 0.335 | M14: 831.72 | N14: 0.0059 | O14: 0.1949 | P14: 0.0044 | Q14: 0.0025 | R14: 0.0428 | S14: 0.2073 | T14: 0.12
A15: avg | B15: =AVERAGE(B3:B14) -> 10.152994
B17: Jan | C17: Feb | D17: Mar | E17: Apr | F17: May | G17: Jun | H17: Jul | I17: Aug | J17: Sep | K17: Oct | L17: Nov | M17: Dec
A18: 0 - 1 | B18: 0 | C18: 0 | D18: 0 | E18: 0 | F18: 0 | G18: 0 | H18: 0 | I18: 0 | J18: 0 | K18: 0 | L18: 0 | M18: 0
A19: 1 - 2 | B19: 0 | C19: 0 | D19: 0 | E19: 0 | F19: 0 | G19: 0 | H19: 0 | I19: 0 | J19: 0 | K19: 0 | L19: 0 | M19: 0
A20: 2 - 3 | B20: 0 | C20: 0 | D20: 0 | E20: 0 | F20: 0 | G20: 0 | H20: 0 | I20: 0 | J20: 0 | K20: 0 | L20: 0 | M20: 0
A21: 3 - 4 | B21: 0 | C21: 0 | D21: 0 | E21: 0 | F21: 0 | G21: 0 | H21: 0 | I21: 0 | J21: 0 | K21: 0 | L21: 0 | M21: 0
A22: 4 - 5 | B22: 0 | C22: 0 | D22: 0 | E22: 0 | F22: 0 | G22: 0 | H22: 0 | I22: 0 | J22: 0 | K22: 0 | L22: 0 | M22: 0
A23: 5 - 6 | B23: 0 | C23: 0 | D23: 0 | E23: 0 | F23: 435.6 | G23: 422.4 | H23: 208.8 | I23: 0 | J23: 0 | K23: 0 | L23: 0 | M23: 0
A24: 6 - 7 | B24: 790.8 | C24: 1087.2 | D24: 3283.2 | E24: 7155.6 | F24: 9340.8 | G24: 8382 | H24: 6572.4 | I24: 5242.8 | J24: 5742 | K24: 5895.6 | L24: 4495.2 | M24: 1381.2
A25: 7 - 8 | B25: 13065.6 | C25: 15160.8 | D25: 20172 | E25: 25394.4 | F25: 25934.4 | G25: 22956 | H25: 19142.4 | I25: 17847.6 | J25: 20140.8 | K25: 21038.4 | L25: 19516.8 | M25: 15045.6
A26: 8 - 9 | B26: 29450.4 | C26: 33339.6 | D26: 39100.8 | E26: 42448.8 | F26: 41641.2 | G26: 36430.8 | H26: 31982.4 | I26: 30135.6 | J26: 34195.2 | K26: 35582.4 | L26: 34366.8 | M26: 30412.8
A27: 9 - 10 | B27: 44073.6 | C27: 48727.2 | D27: 53347.2 | E27: 54668.4 | F27: 52918.8 | G27: 47004 | H27: 41925.6 | I27: 39932.4 | J27: 43678.8 | K27: 46634.4 | L27: 45748.8 | M27: 42806.4
A28: 10 - 11 | B28: 53386.8 | C28: 57891.6 | D28: 60762 | E28: 62203.2 | F28: 59221.2 | G28: 52944 | H28: 47805.6 | I28: 46603.2 | J28: 49910.4 | K28: 52273.2 | L28: 52454.4 | M28: 50238
A29: 11 - 12 | B29: 56154 | C29: 61248 | D29: 64058.4 | E29: 64753.2 | F29: 61335.6 | G29: 54907.2 | H29: 50206.8 | I29: 48448.8 | J29: 51873.6 | K29: 53080.8 | L29: 53450.4 | M29: 51606
... A45: 工作日天数 | B45: 18 | C45: 18 | D45: 20 | E45: 18 | F45: 20 | G45: 18 | H45: 18 | I45: 18 | J45: 18 | K45: 18 | L45: 18 | M45: 18
B46: =B42*B45/1000 -> 7022.0952 | C46: =C42*C45/1000 -> 8030.4048 | D46: =D42*D45/1000 -> 9683.088 | E46: =E42*E45/1000 -> 8925.9624 | F46: =F42*F45/1000 -> 9265.56 | G46: =G42*G45/1000 -> 7522.0056 | H46: =H42*H45/1000 -> 6673.752 | I46: =I42*I45/1000 -> 6378.7176 | ... M46: =M42*M45/1000 -> 6411.3552
A47: 假期天数 | B47: 0 | C47: 0 | D47: 0 | E47: 0 | F47: 0 | G47: 0 | H47: 0 | I47: 0 | J47: 0 | K47: 0 | L47: 0 | M47: 0
B48: =B47*B42/1000 -> 0 | C48: =C47*C42/1000 -> 0 | D48: =D47*D42/1000 -> 0 | E48: =E47*E42/1000 -> 0 | F48: =F47*F42/1000 -> 0 | G48: =G47*G42/1000 -> 0 | H48: =H47*H42/1000 -> 0 | I48: =I47*I42/1000 -> 0 | ... M48: =M47*M42/1000 -> 0
A51: 自投类
B52: Jan | C52: Feb | D52: Mar | E52: Apr | F52: May | G52: Jun | H52: Jul | I52: Aug | J52: Sep | K52: Oct | L52: Nov | M52: Dec
A53: 月发电量 | B53: =B46 -> 7022.0952 | C53: =C46 -> 8030.4048 | D53: =D46 -> 9683.088 | E53: =E46 -> 8925.9624 | F53: =F46 -> 9265.56 | G53: =G46 -> 7522.0056 | H53: =H46 -> 6673.752 | I53: =I46 -> 6378.7176 | ... M53: =M46 -> 6411.3552
A54: 电费单月用电量 | B54: 5760 | C54: 20280 | D54: 21600 | E54: 21960 | F54: 21720 | G54: 19560 | H54: 25440 | I54: 14640 | J54: 25440 | K54: 22800 | L54: 21000 | M54: 26880
A55: 月收益（PHP）（取小） | B55: =B53*13 -> 91287.238 | C55: =C53*13 -> 104395.26 | D55: =D53*13 -> 125880.14 | E55: =E53*13 -> 116037.51 | F55: =F53*13 -> 120452.28 | G55: =G53*13 -> 97786.073 | H55: =H53*13 -> 86758.776 | I55: =I53*13 -> 82923.329 | ... M55: =M53*13 -> 83347.618
A57: 总投资（PHP） | B57: ='成本&报价'!C84 -> 3108259
A58: 首年总收益（PHP） | B58: =SUM(B55:M55)*B59 -> 1054879.6
A59: 收益折扣 | B59: 0.9

Sheet IRR(电费折让30%收费20年）
A1: Lease Period | B1: Investment/Bill Income | C1: Cashflow | D1: IRR PA | E1: Pay Back Period | H1: Discount | I1: Pay Back Period | J1: Fist year cash | K1: IRR PA | L1: Total Cash Inflow
A2: 46357 | B2: =[1]收益!B57 -> 4067816 | C2: =-B2 -> -4067816 | D2: =IRR(C2:C22) -> 0.24925426 | E2: =B2/C3 -> 3.8561898 | G2: 0 | H2: 1 | I2: =E2 -> 3.8561898 | J2: =B3/1000 -> 1054.8796 | K2: =D2 -> 0.24925426 | L2: =C25 -> 20005407
A3: 46722 | B3: =[1]收益!B58 -> 1054879.6 | C3: =B3*B5 -> 1054879.6 | D3: 0.98 | E3: 首年衰减率 | G3: 0.2 | H3: 0.8 | I3: =E29 -> 4.8202372 | J3: =$J$2*H3 -> 843.9037 | K3: =D29 -> 0.19537278 | L3: =C52 -> 16004325
A4: 47088 | B4: Discount 30% | C4: =C3*D3 -> 1033782 | D4: 0.004 | E4: 组件年衰减率 | G4: 0.25 | H4: 0.75 | I4: =E56 -> 5.1415864 | J4: =$J$2*H4 -> 791.15971 | K4: =D56 -> 0.18158139 | L4: =C79 -> 15004055
A5: 47453 | B5: 1 | C5: =C4*(1-$D$4) -> 1029646.9 | G5: 0.3 | H5: 0.7 | I5: =E83 -> 5.5088425 | J5: =$J$2*H5 -> 738.41573 | K5: =D83 -> 0.16760576 | L5: =C106 -> 14003785
A6: 47818 | C6: =C5*(1-$D$4) -> 1025528.3 | G6: 0.35 | H6: 0.65 | I6: =E110 -> 5.9325997 | J6: =$J$2*H6 -> 685.67175 | K6: =D110 -> 0.15340607 | L6: =C133 -> 13003515
A7: 48183 | C7: =C6*(1-$D$4) -> 1021426.2 | G7: 0.4 | H7: 0.6 | I7: =E137 -> 6.426983 | J7: =$J$2*H7 -> 632.92777 | K7: =D137 -> 0.13893237 | L7: =C160 -> 12003244
A8: 48549 | C8: =C7*(1-$D$4) -> 1017340.5 | G8: 0.45 | H8: 0.55 | I8: =E164 -> 7.0112541 | J8: =$J$2*H8 -> 580.18379 | K8: =D164 -> 0.1241212 | L8: =C187 -> 11002974
A9: 48914 | C9: =C8*(1-$D$4) -> 1013271.1 | G9: 0.5 | H9: 0.5 | I9: =E191 -> 7.7123795 | J9: =$J$2*H9 -> 527.43981 | K9: =D191 -> 0.10889065 | L9: =C214 -> 10002704
A10: 49279 | C10: =C9*(1-$D$4) -> 1009218
A11: 49644 | C11: =C10*(1-$D$4) -> 1005181.2
A12: 50010 | C12: =C11*(1-$D$4) -> 1001160.4
A13: 50375 | C13: =C12*(1-$D$4) -> 997155.81
A14: 50740 | C14: =C13*(1-$D$4) -> 993167.18
A15: 51105 | C15: =C14*(1-$D$4) -> 989194.52
A16: 51471 | C16: =C15*(1-$D$4) -> 985237.74
A17: 51836 | C17: =C16*(1-$D$4) -> 981296.79
A18: 52201 | C18: =C17*(1-$D$4) -> 977371.6
A19: 52566 | C19: =C18*(1-$D$4) -> 973462.11
A20: 52932 | C20: =C19*(1-$D$4) -> 969568.26
A21: 53297 | C21: =C20*(1-$D$4) -> 965689.99
A22: 53662 | C22: =C21*(1-$D$4) -> 961827.23
A23: 53662 | B23: Residual | C23: =B24 -> 1
B24: 1 | C24: =C23-B24 -> 0
B25: Total Cash Inflow | C25: =SUM(C3:C24) -> 20005407 | D25: =C25*9 -> 1.8004866e+08
B26: Net Cashflow | C26: =C25+C2 -> 15937591
A28: Lease Period | B28: Investment/Bill Income | C28: Cashflow | D28: IRR PA | E28: Pay Back Period
A29: 46357 | B29: =B2 -> 4067816 | C29: =-B29 -> -4067816 | D29: =IRR(C29:C49) -> 0.19537278 | E29: =B29/C30 -> 4.8202372
A30: 46722 | B30: =B3 -> 1054879.6 | C30: =B30*B32 -> 843903.7 | D30: =D3 -> 0.98 | E30: 首年衰减率
A31: 47088 | B31: Discount 30% | C31: =C30*D30 -> 827025.62 | D31: =D4 -> 0.004 | E31: 组件年衰减率
A32: 47453 | B32: 0.8 | C32: =C31*(1-$D$4) -> 823717.52
A33: 47818 | C33: =C32*(1-$D$4) -> 820422.65
A34: 48183 | C34: =C33*(1-$D$4) -> 817140.96
A35: 48549 | C35: =C34*(1-$D$4) -> 813872.39
A36: 48914 | C36: =C35*(1-$D$4) -> 810616.9
A37: 49279 | C37: =C36*(1-$D$4) -> 807374.44
A38: 49644 | C38: =C37*(1-$D$4) -> 804144.94
A39: 50010 | C39: =C38*(1-$D$4) -> 800928.36
A40: 50375 | C40: =C39*(1-$D$4) -> 797724.65
A41: 50740 | C41: =C40*(1-$D$4) -> 794533.75
...

Sheet IRR(7年后1元转让给业主）
A1: Lease Period | B1: Investment/Electricty Bill Income | C1: Cashflow | D1: IRR PA | E1: IRR PA | F1: Pay Back Period | H1: year | I1: IRR PA | J1: Pay Back Period | K1: Total Cash Inflow | N1: Capital Expenditure | O1: Cumulative Financial Benefit
A2: 46357 | B2: =收益!B57 -> 3108259 | C2: =-B2 -> -3108259 | D2: =IRR(C2:C12) -> 0.30105289 | E2: =(1+D2)^4-1 -> 1.865364 | F2: =B2/B3 -> 2.9465533 | H2: 9 | I2: =D2 -> 0.30105289 | J2: =F2 -> 2.9465533 | K2: =C14 -> 9210274.9 | M2: 0 | N2: =B2/1000 -> 3108.259 | O2: 0
A3: 46722 | B3: =收益!B58 -> 1054879.6 | C3: =B3 -> 1054879.6 | D3: 0.98 | E3: 首年衰减 | H3: 8 | I3: =D19 -> 0.28863707 | J3: =F19 -> 2.9465533 | K3: =C31 -> 8205093.7 | M3: 1 | N3: =N2 -> 3108.259 | O3: =O2+P3 -> 1054.8796 | P3: =C3/1000 -> 1054.8796
A4: 47088 | C4: =D3*C3 -> 1033782 | D4: 0.004 | E4: 组件年衰减率 | H4: 7 | I4: =D36 -> 0.27026087 | J4: =F36 -> 2.9465533 | K4: =C48 -> 7195875.7 | M4: 2 | N4: =N3 -> 3108.259 | O4: =O3+P4 -> 2088.6616 | P4: =C4/1000 -> 1033.782
A5: 47453 | C5: =C4*(1-$D$4) -> 1029646.9 | H5: 6 | I5: =D53 -> 0.24234177 | J5: =F53 -> 2.9465533 | K5: =C65 -> 6182604.5 | M5: 3 | N5: =N4 -> 3108.259 | O5: =O4+P5 -> 3118.3085 | P5: =C5/1000 -> 1029.6469
A6: 47818 | C6: =C5*(1-$D$4) -> 1025528.3 | H6: 5 | I6: =D70 -> 0.19847344 | J6: =F70 -> 2.9465533 | K6: =C82 -> 5165264.1 | M6: 4 | N6: =N5 -> 3108.259 | O6: =O5+P6 -> 4143.8369 | P6: =C6/1000 -> 1025.5283
A7: 48183 | C7: =C6*(1-$D$4) -> 1021426.2 | H7: 4 | I7: =D87 -> 0.12648504 | J7: =F87 -> 2.9465533 | K7: =C99 -> 4143837.9 | M7: 5 | N7: =N6 -> 3108.259 | O7: =O6+P7 -> 5165.2631 | P7: =C7/1000 -> 1021.4262
A8: 48549 | C8: =C7*(1-$D$4) -> 1017340.5 | M8: 6 | N8: =N7 -> 3108.259 | O8: =O7+P8 -> 6182.6035 | P8: =C8/1000 -> 1017.3405
A9: 48914 | C9: =C8*(1-$D$4) -> 1013271.1 | M9: 7 | N9: =N8 -> 3108.259 | O9: =O8+P9 -> 7195.8747 | P9: =C9/1000 -> 1013.2711
A10: 48915 | C10: =C9*(1-$D$4) -> 1009218 | M10: 8 | N10: =N9 -> 3108.259 | O10: =O9+P10 -> 8205.0927 | P10: =C10/1000 -> 1009.218
A11: 48916 | C11: =C10*(1-$D$4) -> 1005181.2 | O11: =O10+P11 -> 9210.2739 | P11: =C11/1000 -> 1005.1812
A12: 48917 | B12: Residual | C12: =B13 -> 1
A13: 48914 | B13: 1 | C13: =C12-B13 -> 0
B14: Total Cash Inflow | C14: =SUM(C3:C13) -> 9210274.9
B15: Net Cashflow | C15: =C14+C2 -> 6102015.9
C16: =C14*9 -> 82892474
A18: Lease Period | B18: Investment/Electricty Bill Income | C18: Cashflow | D18: IRR PA | E18: IRR PA | F18: Pay Back Period
A19: 46357 | B19: =B2 -> 3108259 | C19: =-B19 -> -3108259 | D19: =IRR(C19:C28) -> 0.28863707 | E19: =(1+D19)^4-1 -> 1.7575442 | F19: =B19/B20 -> 2.9465533
A20: 46722 | B20: =B3 -> 1054879.6 | C20: =B20 -> 1054879.6 | D20: =D3 -> 0.98 | E20: =E3 -> 首年衰减
A21: 47088 | C21: =D20*C20 -> 1033782 | D21: =D4 -> 0.004 | E21: =E4 -> 组件年衰减率
A22: 47453 | C22: =C21*(1-$D$4) -> 1029646.9
A23: 47818 | C23: =C22*(1-$D$4) -> 1025528.3
A24: 48183 | C24: =C23*(1-$D$4) -> 1021426.2
A25: 48549 | C25: =C24*(1-$D$4) -> 1017340.5
A26: 48914 | C26: =C25*(1-$D$4) -> 1013271.1
A27: 48915 | C27: =C26*(1-$D$4) -> 1009218
A28: 48916 | C28: 1
A29: 48917 | B29: Residual | C29: 0
A30: 48914 | B30: 1 | C30: 0
B31: Total Cash Inflow | C31: =SUM(C20:C30) -> 8205093.7
B32: Net Cashflow | C32: =C31+C19 -> 5096834.7
C33: =C31*9 -> 73845844
A35: Lease Period | B35: Investment/Electricty Bill Income | C35: Cashflow | D35: IRR PA | E35: IRR PA | F35: Pay Back Period
A36: 46357 | B36: =B19 -> 3108259 | C36: =-B36 -> -3108259 | D36: =IRR(C36:C44) -> 0.27026087 | E36: =(1+D36)^4-1 -> 1.6035845 | F36: =B36/B37 -> 2.9465533
A37: 46722 | B37: =B20 -> 1054879.6 | C37: =B37 -> 1054879.6 | D37: =D20 -> 0.98 | E37: =E20 -> 首年衰减
A38: 47088 | C38: =D37*C37 -> 1033782 | D38: =D21 -> 0.004 | E38: =E21 -> 组件年衰减率
A39: 47453 | C39: =C38*(1-$D$4) -> 1029646.9
A40: 47818 | C40: =C39*(1-$D$4) -> 1025528.3
A41: 48183 | C41: =C40*(1-$D$4) -> 1021426.2
A42: 48549 | C42: =C41*(1-$D$4) -> 1017340.5
...

Sheet PPT
B1: 中文 | C1: 字段 | D1: 数字 | F1: Sub BatchReplaceAll()
A2: =ROW()-1 -> 1 | B2: 装机容量 | C2: {{capacity}} | D2: ='成本&报价'!C15 -> 105.84 | F2: Dim sld As Slide
A3: =ROW()-1 -> 2 | B3: 等效小时数 | C3: {{flh}} | D3: =_xlfn.CEILING.MATH((31*(收益!B42+收益!D42+收益!F42+收益!H42+收益!I42+收益!K42+收益!M42)+30*(收益!E42+收益!G42+收益!J42+收益!L42)+28*收益!C42)/D2/1000,1) -> 1408 | F3: Dim shp As Shape
A4: =ROW()-1 -> 3 | B4: 逆变器数量 | C4: {{inv_count}} | D4: ='成本&报价'!C60 -> 2
A5: =ROW()-1 -> 4 | B5: 组件数量 | C5: {{module_count}} | D5: ='成本&报价'!C4 -> 168 | F5: For Each sld In ActivePresentation.Slides
A6: =ROW()-1 -> 5 | B6: 总投资 | C6: {{total_investment}} | D6: ='IRR(电费折让30%收费20年）'!B2 -> 4067816 | F6: For Each shp In sld.Shapes
A7: =ROW()-1 -> 6 | B7: 首年收益 | C7: {{year1_revenue}} | D7: ='IRR(电费折让30%收费20年）'!B3 -> 1054879.6 | F7: If shp.HasTextFrame And shp.TextFrame.HasText Then
A8: =ROW()-1 -> 7 | B8: 回收周期 | C8: {{payback_period}} | D8: ='IRR(电费折让30%收费20年）'!E2 -> 3.8561898 | F8: With shp.TextFrame.TextRange
A9: =ROW()-1 -> 8 | B9: 20年总收益 | C9: {{rev_20y}} | D9: ='IRR(电费折让30%收费20年）'!L9 -> 10002704 | F9: =G9&H9&I9&J9&K9 -> .Replace "{{capacity}}", "105.84" | G9: .Replace " | H9: =C2 -> {{capacity}} | I9: ", " | J9: =TEXT(D2,"0.00") -> 105.84 | K9: "
A10: =ROW()-1 -> 9 | B10: 20年IRR | C10: {{irr_20y}} | D10: ='IRR(电费折让30%收费20年）'!K9 -> 0.10889065 | F10: =G10&H10&I10&J10&K10 -> .Replace "{{flh}}", "1408" | G10: .Replace " | H10: =C3 -> {{flh}} | I10: ", " | J10: =TEXT(D3,"0") -> 1408 | K10: "
A11: =ROW()-1 -> 10 | B11: 5年卖电站总收益 | C11: {{rev_5y}} | D11: ='IRR(7年后1元转让给业主）'!K6 -> 5165264.1 | F11: =G11&H11&I11&J11&K11 -> .Replace "{{inv_count}}", "2" | G11: .Replace " | H11: =C4 -> {{inv_count}} | I11: ", " | J11: =TEXT(D4,"0") -> 2 | K11: "
A12: =ROW()-1 -> 11 | B12: 5年卖电站IRR | C12: {{irr_5y}} | D12: ='IRR(7年后1元转让给业主）'!I6 -> 0.19847344 | F12: =G12&H12&I12&J12&K12 -> .Replace "{{module_count}}", "168" | G12: .Replace " | H12: =C5 -> {{module_count}} | I12: ", " | J12: =TEXT(D5,"0") -> 168 | K12: "
A13: =ROW()-1 -> 12 | B13: 逆变器功率 | C13: {{inv_power}} | D13: 50 | F13: =G13&H13&I13&J13&K13 -> .Replace "{{total_investment}}", "4,067,816" | G13: .Replace " | H13: =C6 -> {{total_investment}} | I13: ", " | J13: =TEXT(D6,"#,##0") -> 4,067,816 | K13: "
A14: =ROW()-1 -> 13 | B14: 减碳量 | C14: {{carbon_reduction}} | D14: 80 | F14: =G14&H14&I14&J14&K14 -> .Replace "{{year1_revenue}}", "1,054,880" | G14: .Replace " | H14: =C7 -> {{year1_revenue}} | I14: ", " | J14: =TEXT(D7,"#,##0") -> 1,054,880 | K14: "
A15: =ROW()-1 -> 14 | B15: 业主名 | C15: {{pro_own}} | D15: FATIMA UNIVERSITY,LAGUNA | F15: =G15&H15&I15&J15&K15 -> .Replace "{{payback_period}}", "3.86" | G15: .Replace " | H15: =C8 -> {{payback_period}} | I15: ", " | J15: =TEXT(D8,"0.00") -> 3.86 | K15: "
A16: =ROW()-1 -> 15 | B16: 用户地址 | C16: {{adr}} | D16: Lot 2-B Manila S Rd, City of Santa Rosa, 4026 Laguna | F16: =G16&H16&I16&J16&K16 -> .Replace "{{rev_20y}}", "10,002,704" | G16: .Replace " | H16: =C9 -> {{rev_20y}} | I16: ", " | J16: =TEXT(D9,"#,##0") -> 10,002,704 | K16: "
A17: =ROW()-1 -> 16 | B17: 用户经纬度 | C17: {{geographic}} | D17: 14°18'17.09"N 121°06'13.43"E | F17: =G17&H17&I17&J17&K17 -> .Replace "{{irr_20y}}", "10.89%" | G17: .Replace " | H17: =C10 -> {{irr_20y}} | I17: ", " | J17: =TEXT(D10,"0.00%") -> 10.89% | K17: "
A18: =ROW()-1 -> 17 | B18: GHI | C18: {{ghi}} | D18: 1932 | F18: =G18&H18&I18&J18&K18 -> .Replace "{{rev_5y}}", "5,165,264" | G18: .Replace " | H18: =C11 -> {{rev_5y}} | I18: ", " | J18: =TEXT(D11,"#,##0") -> 5,165,264 | K18: "
A19: =ROW()-1 -> 18 | B19: 面积 | C19: {{roof_area}} | D19: 1014.45 | F19: =G19&H19&I19&J19&K19 -> .Replace "{{irr_5y}}", "19.85%" | G19: .Replace " | H19: =C12 -> {{irr_5y}} | I19: ", " | J19: =TEXT(D12,"0.00%") -> 19.85% | K19: "
A20: =ROW()-1 -> 19 | B20: 汇率 | C20: {{Exchg}} | D20: 8.79 | F20: =G20&H20&I20&J20&K20 -> .Replace "{{inv_power}}", "50" | G20: .Replace " | H20: =C13 -> {{inv_power}} | I20: ", " | J20: =TEXT(D13,"0") -> 50 | K20: "
A21: =ROW()-1 -> 20 | B21: 汇率日期 | C21: {{Exchg_date}} | D21: April 2 2006 | F21: =G21&H21&I21&J21&K21 -> .Replace "{{carbon_reduction}}", "80" | G21: .Replace " | H21: =C14 -> {{carbon_reduction}} | I21: ", " | J21: =TEXT(D14,"0") -> 80 | K21: "
A22: =ROW()-1 -> 21 | B22: 逆变器的单位 | C22: {{set}} | D22: sets | F22: =G22&H22&I22&J22&K22 -> .Replace "{{pro_own}}", "FATIMA UNIVERSITY,LAGUNA" | G22: .Replace " | H22: =C15 -> {{pro_own}} | I22: ", " | J22: =TEXT(D15,"0") -> FATIMA UNIVERSITY,LAGUNA | K22: "
A23: =ROW()-1 -> 22 | F23: =G23&H23&I23&J23&K23 -> .Replace "{{adr}}", "Lot 2-B Manila S Rd, City of Santa Rosa, 4026 Laguna" | G23: .Replace " | H23: =C16 -> {{adr}} | I23: ", " | J23: =TEXT(D16,"0") -> Lot 2-B Manila S Rd, City of Santa Rosa, 4026 Laguna | K23: "
B24: global截图 | C24: global | F24: =G24&H24&I24&J24&K24 -> .Replace "{{geographic}}", Chr(34) & "14°18'17.09""N 121°06'13.43""E"& Chr(34) | G24: .Replace " | H24: =C17 -> {{geographic}} | I24: ", Chr(34) & | J24: =""""&SUBSTITUTE(D17,"""","""""")&"""" -> "14°18'17.09""N 121°06'13.43""E" | K24: & Chr(34)
B25: 航拍或卫星图 | C25: aerial | F25: =G25&H25&I25&J25&K25 -> .Replace "{{ghi}}", "1932.0" | G25: .Replace " | H25: =C18 -> {{ghi}} | I25: ", " | J25: =TEXT(D18,"0.0") -> 1932.0 | K25: "
B26: opensloar 组件排布图 | C26: opensloar 1 | F26: =G26&H26&I26&J26&K26 -> .Replace "{{roof_area}}", "1014.45" | G26: .Replace " | H26: =C19 -> {{roof_area}} | I26: ", " | J26: =TEXT(D19,"0.00") -> 1014.45 | K26: "
B27: opensolar 碳排量 | C27: opensloar 2 | F27: =G27&H27&I27&J27&K27 -> .Replace "{{Exchg}}", "8.79" | G27: .Replace " | H27: =C20 -> {{Exchg}} | I27: ", " | J27: =TEXT(D20,"0.00") -> 8.79 | K27: "
B28: 20年曲线 | C28: optionB | F28: =G28&H28&I28&J28&K28 -> .Replace "{{Exchg_date}}", "April 2 2006" | G28: .Replace " | H28: =C21 -> {{Exchg_date}} | I28: ", " | J28: =TEXT(D21,"0.00") -> April 2 2006 | K28: "
B29: 5年曲线 | C29: optionC | F29: =G29&H29&I29&J29&K29 -> .Replace "{{set}}", "sets" | G29: .Replace " | H29: =C22 -> {{set}} | I29: ", " | J29: =TEXT(D22,"0.00") -> sets | K29: "
B30: 报价清单 | C30: Breakdown
F33: End With
F34: End If
F35: Next shp
F36: Next sld
F38: MsgBox "✅ 所有 {{字段}} 已一次性替换完成！"
F39: End Sub
